Workbook

Sheet RESUMEN
B3: MACROPROYECTO | C3: COD | D3: UND | E3: VALOR UNITARIO | F3: VALOR TOTAL | G3: CANT | H3: 1
B4: NODO | H4: 9958
B5: MATERIALES | C5: - | D5: - | E5: - | F5: - | G5: - | H5: -
B6: SERV SUM/INST ABRAZ SIN SDA 10 PULG | C6: 518 | D6: UN | F6: =+G6*E6 -> 0 | G6: =SUM(H6:H6) -> 0 | H6: =+'9958'!D11 -> 0
B7: SERV SUM/INST ABRAZ SIN SDA 4 PULG | C7: 519 | D7: UN | F7: =+G7*E7 -> 0 | G7: =SUM(H7:H7) -> 0 | H7: =+'9958'!D12 -> 0
B8: SERV SUM/INST ABRAZ SIN SDA 5 PULG | C8: 520 | D8: UN | F8: =+G8*E8 -> 0 | G8: =SUM(H8:H8) -> 0 | H8: =+'9958'!D13 -> 0
B9: SERV SUM/INST ABRAZ SIN SDA 6 PULG | C9: 521 | D9: UN | F9: =+G9*E9 -> 0 | G9: =SUM(H9:H9) -> 0 | H9: =+'9958'!D14 -> 0
B10: SERV SUM/INST ABRAZ SIN SDA 7 PULG | C10: 522 | D10: UN | F10: =+G10*E10 -> 0 | G10: =SUM(H10:H10) -> 0 | H10: =+'9958'!D15 -> 0
B11: SERV SUM/INST ABRAZ SIN SDA 8 PULG | C11: 523 | D11: UN | F11: =+G11*E11 -> 0 | G11: =SUM(H11:H11) -> 0 | H11: =+'9958'!D16 -> 0
B12: SERV SUM/INST ABRAZ TIPO CORONA 10 PULG | C12: 524 | D12: UN | F12: =+G12*E12 -> 0 | G12: =SUM(H12:H12) -> 0 | H12: =+'9958'!D17 -> 0
B13: SERV SUM/INST ABRAZ TIPO CORONA 6 PULG | C13: 525 | D13: UN | F13: =+G13*E13 -> 0 | G13: =SUM(H13:H13) -> 0 | H13: =+'9958'!D18 -> 0
B14: SERV SUM/INST ABRAZ TIPO CORONA 7 PULG | C14: 526 | D14: UN | F14: =+G14*E14 -> 0 | G14: =SUM(H14:H14) -> 0 | H14: =+'9958'!D19 -> 0
B15: SERV SUM/INST ABRAZ UNA SDA 10 PULG | C15: 527 | D15: UN | F15: =+G15*E15 -> 0 | G15: =SUM(H15:H15) -> 0 | H15: =+'9958'!D20 -> 0
B16: SERV SUM/INST ABRAZ UNA SDA 4 PULG | C16: 528 | D16: UN | F16: =+G16*E16 -> 0 | G16: =SUM(H16:H16) -> 0 | H16: =+'9958'!D21 -> 0
B17: SERV SUM/INST ABRAZ UNA SDA 5 PULG | C17: 529 | D17: UN | F17: =+G17*E17 -> 0 | G17: =SUM(H17:H17) -> 0 | H17: =+'9958'!D22 -> 0
... B200: POSTE TRASLÚCIDO FABRICADO EN POLIÉSTER REFORZADO CON FIBRA DE VIDRIO (PRFV) 12MTS 510KGF | C200: 712 | D200: UN | F200: =+G200*E200 -> 0 | G200: =SUM(H200:H200) -> 0 | H200: =+'9958'!D205 -> 0
B201: MANO DE OBRA
B202: SERV ALQ EQUIPO CORTAD-OPER-COMBUS-INSU | C202: 190 | D202: UN | F202: =+G202*E202 -> 0 | G202: =SUM(H202:H202) -> 0 | H202: =+'9958'!D207 -> 0
B203: SERV ALQ MACHINE NEUM-COMPRES | C203: 191 | D203: UN | F203: =+G203*E203 -> 0 | G203: =SUM(H203:H203) -> 0 | H203: =+'9958'!D208 -> 0
B204: SERV APERT HUECO POST 11M A 14M Y ANCLAS | C204: 192 | D204: UN | F204: =+G204*E204 -> 0 | G204: =SUM(H204:H204) -> 0 | H204: =+'9958'!D209 -> 0
B205: SERV APERT HUECO POST PRIM 11A14 MTS | C205: 193 | D205: UN | F205: =+G205*E205 -> 0 | G205: =SUM(H205:H205) -> 0 | H205: =+'9958'!D210 -> 0
B206: SERV APERT HUECO POST SECUND 8 A 10 MTS | C206: 194 | D206: UN | F206: =+G206*E206 -> 0 | G206: =SUM(H206:H206) -> 0 | H206: =+'9958'!D211 -> 0
B207: SERV APLOMADA POST CONC 11A14 MTS | C207: 195 | D207: UN | F207: =+G207*E207 -> 0 | G207: =SUM(H207:H207) -> 0 | H207: =+'9958'!D212 -> 0
B208: SERV APLOMADA POST CONC 8 A 10 MTS | C208: 196 | D208: UN | E208: 50897 | F208: =+G208*E208 -> 0 | G208: =SUM(H208:H208) -> 0 | H208: =+'9958'!D213 -> 0
B209: SERV APLOMADA POST MET Y-O FIBRA 11A14M | C209: 197 | D209: UN | E209: 47859 | F209: =+G209*E209 -> 0 | G209: =SUM(H209:H209) -> 0 | H209: =+'9958'!D214 -> 0
B210: SERV APLOMADA POST MET Y-O FIBRA 8A10M | C210: 198 | D210: UN | E210: 37598 | F210: =+G210*E210 -> 0 | G210: =SUM(H210:H210) -> 0 | H210: =+'9958'!D215 -> 0
B211: SERV ARMADO IZAJE MAST 14A24M HINC Y APL | C211: 199 | D211: UN | F211: =+G211*E211 -> 0 | G211: =SUM(H211:H211) -> 0 | H211: =+'9958'!D216 -> 0
B212: SERV BASE DE CONCRETO PARA POSTE 9 MTS | C212: 200 | D212: UN | F212: =+G212*E212 -> 0 | G212: =SUM(H212:H212) -> 0 | H212: =+'9958'!D217 -> 0
B213: SERV BASE POST MET TIPO KEISON 10A12M | C213: 201 | D213: UN | F213: =+G213*E213 -> 0 | G213: =SUM(H213:H213) -> 0 | H213: =+'9958'!D218 -> 0
B214: SERV BOTADO DE ESCOMBROS | C214: 202 | D214: M3 | E214: 29161 | F214: =+G214*E214 -> 0 | G214: =SUM(H214:H214) -> 0 | H214: =+'9958'!D219 -> 0
B215: SERV CAJA AP 0.4X0.4M INC MAT E INST | C215: 203 | D215: UN | E215: 298000 | F215: =+G215*E215 -> 0 | G215: =SUM(H215:H215) -> 0 | H215: =+'9958'!D220 -> 0
B216: SERV CAMARA BT NORMA EMCALI | C216: 204 | D216: UN | F216: =+G216*E216 -> 0 | G216: =SUM(H216:H216) -> 0 | H216: =+'9958'!D221 -> 0
B217: SERV CAMARA TIPO I NORMA EMCALI | C217: 205 | D217: UN | F217: =+G217*E217 -> 0 | G217: =SUM(H217:H217) -> 0 | H217: =+'9958'!D222 -> 0
B218: SERV CAMBIO BOMBILLA A CMH CAMIONETA | C218: 206 | D218: UN | F218: =+G218*E218 -> 0 | G218: =SUM(H218:H218) -> 0 | H218: =+'9958'!D223 -> 0
B219: SERV CAMBIO DE BOMBILLA A CMH CANASTA | C219: 207 | D219: UN | F219: =+G219*E219 -> 0 | G219: =SUM(H219:H219) -> 0 | H219: =+'9958'!D224 -> 0
B220: SERV CAMBIO FOTOCELDA TEMP EN CAMIONETA | C220: 208 | D220: UN | F220: =+G220*E220 -> 0 | G220: =SUM(H220:H220) -> 0 | H220: =+'9958'!D225 -> 0
B221: SERV CAMBIO FOTOCELDA TEMP EN CANASTA | C221: 209 | D221: UN | F221: =+G221*E221 -> 0 | G221: =SUM(H221:H221) -> 0 | H221: =+'9958'!D226 -> 0
B222: SERV CONCRETA POST CONC 8A12M INC MAT MO | C222: 210 | D222: UN | F222: =+G222*E222 -> 0 | G222: =SUM(H222:H222) -> 0 | H222: =+'9958'!D227 -> 0
B223: SERV CONCRETA POST FIBR 8A12M INC MAT MO | C223: 211 | D223: UN | F223: =+G223*E223 -> 0 | G223: =SUM(H223:H223) -> 0 | H223: =+'9958'!D228 -> 0
B224: SERV CONCRETA ENTRE POST Y CAJA | C224: 212 | D224: UN | F224: =+G224*E224 -> 0 | G224: =SUM(H224:H224) -> 0 | H224: =+'9958'!D229 -> 0
...

Sheet 9958
B3: PROYECTO No. 9966 | C3: COD | D3: CANT. TOTAL
B4: NODO
B5: CODIGO DE LUMINARIA | C5: - | D5: -
B6: POTENCIA INSTALADA | C6: - | D6: -
B7: CODIGO FOTOCELDA | C7: - | D7: -
B8: LUMINARIA EMCALI (E) /CONTRATISTA (C ) | C8: - | D8: -
B9: LUMINARIA MODERNIZACION (M) /EXPANSION (E) | C9: - | D9: -
B10: MATERIALES
B11: SERV SUM/INST ABRAZ SIN SDA 10 PULG | C11: 518 | D11: =SUM(E11:U11) -> 0
B12: SERV SUM/INST ABRAZ SIN SDA 4 PULG | C12: 519 | D12: =SUM(E12:U12) -> 0
B13: SERV SUM/INST ABRAZ SIN SDA 5 PULG | C13: 520 | D13: =SUM(E13:U13) -> 0
B14: SERV SUM/INST ABRAZ SIN SDA 6 PULG | C14: 521 | D14: =SUM(E14:U14) -> 0
B15: SERV SUM/INST ABRAZ SIN SDA 7 PULG | C15: 522 | D15: =SUM(E15:U15) -> 0
B16: SERV SUM/INST ABRAZ SIN SDA 8 PULG | C16: 523 | D16: =SUM(E16:U16) -> 0
B17: SERV SUM/INST ABRAZ TIPO CORONA 10 PULG | C17: 524 | D17: =SUM(E17:U17) -> 0
B18: SERV SUM/INST ABRAZ TIPO CORONA 6 PULG | C18: 525 | D18: =SUM(E18:U18) -> 0
B19: SERV SUM/INST ABRAZ TIPO CORONA 7 PULG | C19: 526 | D19: =SUM(E19:U19) -> 0
B20: SERV SUM/INST ABRAZ UNA SDA 10 PULG | C20: 527 | D20: =SUM(E20:U20) -> 0
B21: SERV SUM/INST ABRAZ UNA SDA 4 PULG | C21: 528 | D21: =SUM(E21:U21) -> 0
B22: SERV SUM/INST ABRAZ UNA SDA 5 PULG | C22: 529 | D22: =SUM(E22:U22) -> 0
... B205: POSTE TRASLÚCIDO FABRICADO EN POLIÉSTER REFORZADO CON FIBRA DE VIDRIO (PRFV) 12MTS 510KGF | C205: 712 | D205: =SUM(E205:U205) -> 0
B206: MANO DE OBRA
B207: SERV ALQ EQUIPO CORTAD-OPER-COMBUS-INSU | C207: 190 | D207: =SUM(E207:U207) -> 0
B208: SERV ALQ MACHINE NEUM-COMPRES | C208: 191 | D208: =SUM(E208:U208) -> 0
B209: SERV APERT HUECO POST 11M A 14M Y ANCLAS | C209: 192 | D209: =SUM(E209:U209) -> 0 | E209: =+E205+E151+E152+E147+E148 -> 0
B210: SERV APERT HUECO POST PRIM 11A14 MTS | C210: 193 | D210: =SUM(E210:U210) -> 0
B211: SERV APERT HUECO POST SECUND 8 A 10 MTS | C211: 194 | D211: =SUM(E211:U211) -> 0 | E211: =+E203+E204+E155+E154+E150+E146 -> 0
B212: SERV APLOMADA POST CONC 11A14 MTS | C212: 195 | D212: =SUM(E212:U212) -> 0 | E212: =+E148+E147 -> 0
B213: SERV APLOMADA POST CONC 8 A 10 MTS | C213: 196 | D213: =SUM(E213:U213) -> 0 | E213: =+E149+E146 -> 0
B214: SERV APLOMADA POST MET Y-O FIBRA 11A14M | C214: 197 | D214: =SUM(E214:U214) -> 0 | E214: =+E183+E184+E151+E152 -> 0
B215: SERV APLOMADA POST MET Y-O FIBRA 8A10M | C215: 198 | D215: =SUM(E215:U215) -> 0 | E215: =+E154+E155+E150+E181+E182 -> 0
B216: SERV ARMADO IZAJE MAST 14A24M HINC Y APL | C216: 199 | D216: =SUM(E216:U216) -> 0
B217: SERV BASE DE CONCRETO PARA POSTE 9 MTS | C217: 200 | D217: =SUM(E217:U217) -> 0
B218: SERV BASE POST MET TIPO KEISON 10A12M | C218: 201 | D218: =SUM(E218:U218) -> 0
B219: SERV BOTADO DE ESCOMBROS | C219: 202 | D219: =SUM(E219:U219) -> 0
B220: SERV CAJA AP 0.4X0.4M INC MAT E INST | C220: 203 | D220: =SUM(E220:U220) -> 0
B221: SERV CAMARA BT NORMA EMCALI | C221: 204 | D221: =SUM(E221:U221) -> 0
B222: SERV CAMARA TIPO I NORMA EMCALI | C222: 205 | D222: =SUM(E222:U222) -> 0
B223: SERV CAMBIO BOMBILLA A CMH CAMIONETA | C223: 206 | D223: =SUM(E223:U223) -> 0
B224: SERV CAMBIO DE BOMBILLA A CMH CANASTA | C224: 207 | D224: =SUM(E224:U224) -> 0
...
